<?xml version="1.0" ?>

<!--

    This sdf file is adapted from the Gazebo diff_drive plugin demo found at
    '/opt/ros/kilted/opt/gz_sim_vendor/share/gz/gz-sim9/worlds/diff_drive.sdf'

    NOTE: In order to have non-primitive models, a 'meshes' folder is required.
    Boxes, spheres, and cylinders, for example, are considered primitive.

-->

<sdf version="1.6">
    <model name='diff_drive_blu'>
      <pose>0 0 0 0 0 0</pose>

      <!--
        Add frame for the LiDAR 
      -->

      <link name="lidar_frame">
        <pose relative_to='chassis'>0.8 0 0.5 0 0 0</pose>
        <inertial>
          <mass>0.1</mass>
          <inertia>
            <ixx>0.001</ixx>
            <iyy>0.001</iyy>
            <izz>0.001</izz>
          </inertia>
        </inertial>
        <visual name='visual'>
          <geometry>
            <cylinder>
              <radius>0.15</radius>
              <length>0.1</length>
            </cylinder>
          </geometry>
          <material>
            <ambient>0 0 0 1</ambient>
            <diffuse>0 0 0 1</diffuse>
          </material>
        </visual>
        <sensor name='lidar' type='lidar'>
          <pose relative_to='lidar_frame'>0 0 0 0 0 0</pose>
          <visualize>true</visualize>
          <update_rate>10</update_rate>
          <ray>
            <scan>
              <horizontal>
                <samples>640</samples>
                <resolution>1</resolution>
                <min_angle>-1.396263</min_angle>
                <max_angle>1.396263</max_angle>
              </horizontal>
              <vertical>
                <samples>1</samples>
                <resolution>0.01</resolution>
                <min_angle>0</min_angle>
                <max_angle>0</max_angle>
              </vertical>
            </scan>
            <range>
              <min>0.08</min>
              <max>30.0</max>
              <resolution>0.01</resolution>
            </range>
          </ray>
          <topic>/model/diff_drive_blu/chassis_lidar/forward</topic>
          <gz_frame_id>diff_drive_blu/lidar_frame</gz_frame_id>
          <always_on>true</always_on>
        </sensor>
      </link>

      <!-- 
        Add the LiDAR as a join to the chassis
      -->

      <joint name='lidar_joint' type='fixed'>
        <parent>chassis</parent>
        <child>lidar_frame</child>
      </joint> 

      <link name='chassis'>
        <pose>-0.151427 -0 0.175 0 -0 0</pose>
        <inertial>
          <mass>1.14395</mass>
          <inertia>
            <ixx>0.126164</ixx>
            <ixy>0</ixy>
            <ixz>0</ixz>
            <iyy>0.416519</iyy>
            <iyz>0</iyz>
            <izz>0.481014</izz>
          </inertia>
        </inertial>
        <visual name='visual'>
          <geometry>
            <box>
              <size>2.01142 1 0.568726</size>
            </box>
          </geometry>
          <material>
            <ambient>0.2 0.5 1.0 1</ambient>
            <diffuse>0.2 0.5 1.0 1</diffuse>
            <specular>0.0 0.0 1.0 1</specular>
          </material>
        </visual>
        <collision name='collision'>
          <geometry>
            <box>
              <size>2.01142 1 0.568726</size>
            </box>
          </geometry>
        </collision>
      </link>

      <link name='left_wheel'>
        <pose>0.554283 0.625029 -0.025 -1.5707 0 0</pose>
        <inertial>
          <mass>2</mass>
          <inertia>
            <ixx>0.145833</ixx>
            <ixy>0</ixy>
            <ixz>0</ixz>
            <iyy>0.145833</iyy>
            <iyz>0</iyz>
            <izz>0.125</izz>
          </inertia>
        </inertial>
        <visual name='visual'>
          <geometry>
            <cylinder>
              <radius>0.3</radius>
              <length>0.3</length>
            </cylinder>
          </geometry>
          <material>
            <ambient>1.0 1.0 1.0 1</ambient>
            <diffuse>1.0 1.0 1.0 1</diffuse>
            <specular>1.0 1.0 1.0 1</specular>
          </material>
        </visual>
        <collision name='collision'>
          <geometry>
            <cylinder>
              <radius>0.3</radius>
              <length>0.3</length>
            </cylinder>
          </geometry>
          <surface>
            <friction>
              <ode>
                <mu>1</mu>
                <mu2>1</mu2>
                <slip1>0.035</slip1>
                <slip2>0</slip2>
                <fdir1>0 0 1</fdir1>
              </ode>
              <bullet>
                <friction>1</friction>
                <friction2>1</friction2>
                <rolling_friction>0.1</rolling_friction>
              </bullet>
            </friction>
          </surface>
        </collision>
      </link>

      <link name='right_wheel'>
        <pose>0.554282 -0.625029 -0.025 -1.5707 0 0</pose>
        <inertial>
          <mass>2</mass>
          <inertia>
            <ixx>0.145833</ixx>
            <ixy>0</ixy>
            <ixz>0</ixz>
            <iyy>0.145833</iyy>
            <iyz>0</iyz>
            <izz>0.125</izz>
          </inertia>
        </inertial>
        <visual name='visual'>
          <geometry>
            <cylinder>
              <radius>0.3</radius>
              <length>0.3</length>
            </cylinder>
          </geometry>
          <material>
            <ambient>1.0 1.0 1.0 1</ambient>
            <diffuse>1.0 1.0 1.0 1</diffuse>
            <specular>1.0 1.0 1.0 1</specular>
          </material>
        </visual>
        <collision name='collision'>
          <geometry>
            <cylinder>
              <radius>0.3</radius>
              <length>0.3</length>
            </cylinder>
          </geometry>
          <surface>
            <friction>
              <ode>
                <mu>1</mu>
                <mu2>1</mu2>
                <slip1>0.035</slip1>
                <slip2>0</slip2>
                <fdir1>0 0 1</fdir1>
              </ode>
              <bullet>
                <friction>1</friction>
                <friction2>1</friction2>
                <rolling_friction>0.1</rolling_friction>
              </bullet>
            </friction>
          </surface>
        </collision>
      </link>

      <link name='caster'>
        <pose>-0.957138 -0 -0.125 0 -0 0</pose>
        <inertial>
          <mass>1</mass>
          <inertia>
            <ixx>0.1</ixx>
            <ixy>0</ixy>
            <ixz>0</ixz>
            <iyy>0.1</iyy>
            <iyz>0</iyz>
            <izz>0.1</izz>
          </inertia>
        </inertial>
        <visual name='visual'>
          <geometry>
            <sphere>
              <radius>0.2</radius>
            </sphere>
          </geometry>
          <material>
            <ambient>0.0 0.0 0.0 1</ambient>
            <diffuse>0.0 0.0 0.0 1</diffuse>
            <specular>0.0 0.0 0.0 1</specular>
          </material>
        </visual>
        <collision name='collision'>
          <geometry>
            <sphere>
              <radius>0.2</radius>
            </sphere>
          </geometry>
        </collision>
      </link>

      <joint name='left_wheel_joint' type='revolute'>
        <parent>chassis</parent>
        <child>left_wheel</child>
        <axis>
          <xyz>0 0 1</xyz>
          <limit>
            <lower>-1.79769e+308</lower>
            <upper>1.79769e+308</upper>
          </limit>
        </axis>
      </joint>

      <joint name='right_wheel_joint' type='revolute'>
        <parent>chassis</parent>
        <child>right_wheel</child>
        <axis>
          <xyz>0 0 1</xyz>
          <limit>
            <lower>-1.79769e+308</lower>
            <upper>1.79769e+308</upper>
          </limit>
        </axis>
      </joint>

      <joint name='caster_wheel' type='ball'>
        <parent>chassis</parent>
        <child>caster</child>
      </joint>

      <!--
        Gazebo plugin for differential drive bot
      -->
      <plugin
        filename="gz-sim-diff-drive-system"
        name="gz::sim::systems::DiffDrive">

        <!--
          Specifies the joints that control the left and right wheels
        -->
        <left_joint>left_wheel_joint</left_joint>
        <right_joint>right_wheel_joint</right_joint>

        <!--
          Distance between the two wheels of the robot
        -->
        <wheel_separation>1.25</wheel_separation>

        <!--
          Radius of the wheels (important for computing rotation speed)
        -->
        <wheel_radius>0.3</wheel_radius>

        <!--
          How often the plugin publishes position and orientation (sec)
        -->
        <odom_publish_frequency>1</odom_publish_frequency>

        <!--
          Lin accel is measured in m/s^2
        -->
        <max_linear_acceleration>1</max_linear_acceleration>
        <min_linear_acceleration>-1</min_linear_acceleration>

        <!--
          Ang accel is measured in radians/s^2
        -->
        <max_angular_acceleration>2</max_angular_acceleration>
        <min_angular_acceleration>-2</min_angular_acceleration>

        <!--
          Lin vel is measured in m/s
        -->
        <max_linear_velocity>1.0</max_linear_velocity>
        <min_linear_velocity>-1.0</min_linear_velocity>

        <!--
          Ang vel is measured in radians/s
        -->
        <max_angular_velocity>1</max_angular_velocity>
        <min_angular_velocity>-1</min_angular_velocity>

        <!--
          Specify the topic for communication
        -->
        <topic>/model/diff_drive_blu/cmd_vel</topic>

      </plugin>

    </model>
</sdf>
